Workbook

Sheet 대시보드
A1: SP-2100 / TL-2200 · PEEL FORCE EVALUATION DASHBOARD
A3: 박리력 비교 그래프 (Force-Time) | 체크된 샘플만 표시됩니다.
A5: ━━━━ 제품 | E5: ━━━━ 제품 | I5: ━━━━ 제품 | M5: ━━━━ 제품
A6: ━━━━ 제품
A32: 샘플 선택 및 구간 분석 | 시작/종료 시간(s)을 입력하면 해당 구간의 평균·최소·최대가 자동 계산됩니다.
A33: 📍 구간 분석 설정: | B33: 시작 시간 (s): | C33: 1 | D33: ~ 종료 시간 (s): | E33: 6 | F33: ※ 위 시작/종료 시간(s)을 입력하면 아래 표의 구간 평균·최소·최대값이 실시간 계산됩니다.
A34: 선택 | B34: # | C34: 제품명 | D34: 공식 AVG (g) | E34: 구간 평균 (g) | F34: 구간 최소 (g) | G34: 구간 최대 (g) | H34: SP (g) | I34: KP (g) | J34: VAL (g) | K34: RMS (g) | L34: 속도 (in/min) | M34: 지연 (s) | N34: 평균시간 (s)
A35: ☑ | B35: 1-1 | C35: 제품 | D35: 13.04 | E35: =AVERAGEIFS('Raw Data'!B$9:B$4808,'Raw Data'!A$9:A$4808,">="&$C$33,'Raw Data'!A$9:A$4808,"<="&$E$33) -> 10.17 | F35: =MINIFS('Raw Data'!B$9:B$4808,'Raw Data'!A$9:A$4808,">="&$C$33,'Raw Data'!A$9:A$4808,"<="&$E$33) -> -0.87 | G35: =MAXIFS('Raw Data'!B$9:B$4808,'Raw Data'!A$9:A$4808,">="&$C$33,'Raw Data'!A$9:A$4808,"<="&$E$33) -> 18.47 | H35: 14.1 | I35: 18.5 | J35: 5.3 | K35: 1.5 | L35: 94.5 | M35: 1 | N35: 5
A36: ☑ | B36: 1-2 | C36: 제품 | D36: 15 | E36: =AVERAGEIFS('Raw Data'!E$9:E$4808,'Raw Data'!D$9:D$4808,">="&$C$33,'Raw Data'!D$9:D$4808,"<="&$E$33) -> 11.52 | F36: =MINIFS('Raw Data'!E$9:E$4808,'Raw Data'!D$9:D$4808,">="&$C$33,'Raw Data'!D$9:D$4808,"<="&$E$33) -> 7.21 | G36: =MAXIFS('Raw Data'!E$9:E$4808,'Raw Data'!D$9:D$4808,">="&$C$33,'Raw Data'!D$9:D$4808,"<="&$E$33) -> 28.85 | H36: 17.7 | I36: 28.8 | J36: 12 | K36: 2.4 | L36: 94.5 | M36: 1 | N36: 5
A37: ☑ | B37: 1-3 | C37: 제품 | D37: 14.17 | E37: =AVERAGEIFS('Raw Data'!H$9:H$4808,'Raw Data'!G$9:G$4808,">="&$C$33,'Raw Data'!G$9:G$4808,"<="&$E$33) -> 12.02 | F37: =MINIFS('Raw Data'!H$9:H$4808,'Raw Data'!G$9:G$4808,">="&$C$33,'Raw Data'!G$9:G$4808,"<="&$E$33) -> 8.68 | G37: =MAXIFS('Raw Data'!H$9:H$4808,'Raw Data'!G$9:G$4808,">="&$C$33,'Raw Data'!G$9:G$4808,"<="&$E$33) -> 18.12 | H37: 16.3 | I37: 18.1 | J37: 12 | K37: 0.8 | L37: 94.5 | M37: 1 | N37: 5
A38: ☑ | B38: 1-4 | C38: 제품 | D38: 13.25 | E38: =AVERAGEIFS('Raw Data'!K$9:K$4808,'Raw Data'!J$9:J$4808,">="&$C$33,'Raw Data'!J$9:J$4808,"<="&$E$33) -> 9.79 | F38: =MINIFS('Raw Data'!K$9:K$4808,'Raw Data'!J$9:J$4808,">="&$C$33,'Raw Data'!J$9:J$4808,"<="&$E$33) -> 3.76 | G38: =MAXIFS('Raw Data'!K$9:K$4808,'Raw Data'!J$9:J$4808,">="&$C$33,'Raw Data'!J$9:J$4808,"<="&$E$33) -> 21.32 | H38: 13.6 | I38: 21.3 | J38: 9 | K38: 1.3 | L38: 94.5 | M38: 1 | N38: 5
A39: ☑ | B39: 1-5 | C39: 제품 | D39: 27.79 | E39: =AVERAGEIFS('Raw Data'!N$9:N$4808,'Raw Data'!M$9:M$4808,">="&$C$33,'Raw Data'!M$9:M$4808,"<="&$E$33) -> 9.79 | F39: =MINIFS('Raw Data'!N$9:N$4808,'Raw Data'!M$9:M$4808,">="&$C$33,'Raw Data'!M$9:M$4808,"<="&$E$33) -> 3.76 | G39: =MAXIFS('Raw Data'!N$9:N$4808,'Raw Data'!M$9:M$4808,">="&$C$33,'Raw Data'!M$9:M$4808,"<="&$E$33) -> 21.32 | H39: 25.3 | I39: 50.7 | J39: 1 | K39: 10.7 | L39: 94.5 | M39: 1 | N39: 5
A41: ※ 표의 첫 번째 열(선택)의 체크박스(☑ / ☐)를 변경하면 차트에 해당 곡선이 실시간으로 켜지거나 숨겨집니다.

Sheet Raw Data
A1: 제품명 | B1: 제품 | D1: 제품명 | E1: 제품 | G1: 제품명 | H1: 제품 | J1: 제품명 | K1: 제품 | M1: 제품명 | N1: 제품
A2: 평균값 (AVG) | B2: 13.04 g | D2: 평균값 (AVG) | E2: 15.00 g | G2: 평균값 (AVG) | H2: 14.17 g | J2: 평균값 (AVG) | K2: 13.25 g | M2: 평균값 (AVG) | N2: 27.79 g
A3: 초기값 (SP) | B3: 14.1 g | D3: 초기값 (SP) | E3: 17.7 g | G3: 초기값 (SP) | H3: 16.3 g | J3: 초기값 (SP) | K3: 13.6 g | M3: 초기값 (SP) | N3: 25.3 g
A4: 피크값 (KP) | B4: 18.5 g | D4: 피크값 (KP) | E4: 28.8 g | G4: 피크값 (KP) | H4: 18.1 g | J4: 피크값 (KP) | K4: 21.3 g | M4: 피크값 (KP) | N4: 50.7 g
A5: 종료값 (VAL) | B5: 5.3 g | D5: 종료값 (VAL) | E5: 12.0 g | G5: 종료값 (VAL) | H5: 12.0 g | J5: 종료값 (VAL) | K5: 9.0 g | M5: 종료값 (VAL) | N5: 1.0 g
A6: 변동치 (RMS) | B6: 1.5 g | D6: 변동치 (RMS) | E6: 2.4 g | G6: 변동치 (RMS) | H6: 0.8 g | J6: 변동치 (RMS) | K6: 1.3 g | M6: 변동치 (RMS) | N6: 10.7 g
A7: 시험 속도 | B7: 94.5 in/min | D7: 시험 속도 | E7: 94.5 in/min | G7: 시험 속도 | H7: 94.5 in/min | J7: 시험 속도 | K7: 94.5 in/min | M7: 시험 속도 | N7: 94.5 in/min
A8: 초기 지연 | B8: 1 s | D8: 초기 지연 | E8: 1 s | G8: 초기 지연 | H8: 1 s | J8: 초기 지연 | K8: 1 s | M8: 초기 지연 | N8: 1 s
A9: 평균 시간 | B9: 5 s | D9: 평균 시간 | E9: 5 s | G9: 평균 시간 | H9: 5 s | J9: 평균 시간 | K9: 5 s | M9: 평균 시간 | N9: 5 s
A10: 총 샘플 수 | B10: 4800 | D10: 총 샘플 수 | E10: 4800 | G10: 총 샘플 수 | H10: 4800 | J10: 총 샘플 수 | K10: 4800 | M10: 총 샘플 수 | N10: 4800
A11: 시간 (s) | B11: 힘 (g) | D11: 시간 (s) | E11: 힘 (g) | G11: 시간 (s) | H11: 힘 (g) | J11: 시간 (s) | K11: 힘 (g) | M11: 시간 (s) | N11: 힘 (g)
A12: 0 | B12: -9.78 | D12: 0 | E12: -8.22 | G12: 0 | H12: -9.88 | J12: 0 | K12: -9.14 | M12: 0 | N12: -9.14
A13: 0.0013 | B13: -0.65 | D13: 0.0013 | E13: -1.37 | G13: 0.0013 | H13: -1.32 | J13: 0.0013 | K13: -1.62 | M13: 0.0013 | N13: -1.62
A14: 0.0025 | B14: -1.2 | D14: 0.0025 | E14: -0.91 | G14: 0.0025 | H14: -1.87 | J14: 0.0025 | K14: -1.32 | M14: 0.0025 | N14: -1.32
A15: 0.0038 | B15: -0.76 | D15: 0.0038 | E15: -0.64 | G15: 0.0038 | H15: -2.2 | J15: 0.0038 | K15: -1.52 | M15: 0.0038 | N15: -1.52
A16: 0.005 | B16: -0.76 | D16: 0.005 | E16: -1.19 | G16: 0.005 | H16: -1.54 | J16: 0.005 | K16: -1.62 | M16: 0.005 | N16: -1.62
A17: 0.0063 | B17: -1.52 | D17: 0.0063 | E17: -1.37 | G17: 0.0063 | H17: -1.76 | J17: 0.0063 | K17: -1.62 | M17: 0.0063 | N17: -1.62
A18: 0.0075 | B18: -1.52 | D18: 0.0075 | E18: -1.1 | G18: 0.0075 | H18: -1.98 | J18: 0.0075 | K18: -1.42 | M18: 0.0075 | N18: -1.42
A19: 0.0088 | B19: -1.2 | D19: 0.0088 | E19: -0.91 | G19: 0.0088 | H19: -1.87 | J19: 0.0088 | K19: -1.62 | M19: 0.0088 | N19: -1.62
A20: 0.01 | B20: -1.3 | D20: 0.01 | E20: -1.37 | G20: 0.01 | H20: -1.98 | J20: 0.01 | K20: -1.83 | M20: 0.01 | N20: -1.83
A21: 0.0113 | B21: -1.3 | D21: 0.0113 | E21: -1.28 | G21: 0.0113 | H21: -2.09 | J21: 0.0113 | K21: -1.42 | M21: 0.0113 | N21: -1.42
A22: 0.0125 | B22: -1.52 | D22: 0.0125 | E22: -0.91 | G22: 0.0125 | H22: -2.09 | J22: 0.0125 | K22: -1.32 | M22: 0.0125 | N22: -1.32
A23: 0.0138 | B23: -0.87 | D23: 0.0138 | E23: -1.37 | G23: 0.0138 | H23: -1.87 | J23: 0.0138 | K23: -1.62 | M23: 0.0138 | N23: -1.62
... A4811: 6 | B4811: 2.06 | D4811: 6 | E4811: 11.32 | G4811: 6 | H4811: 12.52 | J4811: 6 | K4811: 5.79 | M4811: 6 | N4811: 5.79

Sheet _ChartData
A1: Sample | B1: Time | C1: Force
A2: 제품 | B2: ='Raw Data'!A9 -> 0 | C2: =IF(OR('대시보드'!$A$35="☑",'대시보드'!$A$35=TRUE,'대시보드'!$A$35="TRUE",'대시보드'!$A$35=1),'Raw Data'!B9,NA()) -> -9.78
A3: 제품 | B3: ='Raw Data'!A10 -> 0.0013 | C3: =IF(OR('대시보드'!$A$35="☑",'대시보드'!$A$35=TRUE,'대시보드'!$A$35="TRUE",'대시보드'!$A$35=1),'Raw Data'!B10,NA()) -> -0.65
A4: 제품 | B4: ='Raw Data'!A11 -> 0.0025 | C4: =IF(OR('대시보드'!$A$35="☑",'대시보드'!$A$35=TRUE,'대시보드'!$A$35="TRUE",'대시보드'!$A$35=1),'Raw Data'!B11,NA()) -> -1.2
A5: 제품 | B5: ='Raw Data'!A12 -> 0.0038 | C5: =IF(OR('대시보드'!$A$35="☑",'대시보드'!$A$35=TRUE,'대시보드'!$A$35="TRUE",'대시보드'!$A$35=1),'Raw Data'!B12,NA()) -> -0.76
A6: 제품 | B6: ='Raw Data'!A13 -> 0.005 | C6: =IF(OR('대시보드'!$A$35="☑",'대시보드'!$A$35=TRUE,'대시보드'!$A$35="TRUE",'대시보드'!$A$35=1),'Raw Data'!B13,NA()) -> -0.76
A7: 제품 | B7: ='Raw Data'!A14 -> 0.0063 | C7: =IF(OR('대시보드'!$A$35="☑",'대시보드'!$A$35=TRUE,'대시보드'!$A$35="TRUE",'대시보드'!$A$35=1),'Raw Data'!B14,NA()) -> -1.52
A8: 제품 | B8: ='Raw Data'!A15 -> 0.0075 | C8: =IF(OR('대시보드'!$A$35="☑",'대시보드'!$A$35=TRUE,'대시보드'!$A$35="TRUE",'대시보드'!$A$35=1),'Raw Data'!B15,NA()) -> -1.52
A9: 제품 | B9: ='Raw Data'!A16 -> 0.0088 | C9: =IF(OR('대시보드'!$A$35="☑",'대시보드'!$A$35=TRUE,'대시보드'!$A$35="TRUE",'대시보드'!$A$35=1),'Raw Data'!B16,NA()) -> -1.2
A10: 제품 | B10: ='Raw Data'!A17 -> 0.01 | C10: =IF(OR('대시보드'!$A$35="☑",'대시보드'!$A$35=TRUE,'대시보드'!$A$35="TRUE",'대시보드'!$A$35=1),'Raw Data'!B17,NA()) -> -1.3
A11: 제품 | B11: ='Raw Data'!A18 -> 0.0113 | C11: =IF(OR('대시보드'!$A$35="☑",'대시보드'!$A$35=TRUE,'대시보드'!$A$35="TRUE",'대시보드'!$A$35=1),'Raw Data'!B18,NA()) -> -1.3
A12: 제품 | B12: ='Raw Data'!A19 -> 0.0125 | C12: =IF(OR('대시보드'!$A$35="☑",'대시보드'!$A$35=TRUE,'대시보드'!$A$35="TRUE",'대시보드'!$A$35=1),'Raw Data'!B19,NA()) -> -1.52
A13: 제품 | B13: ='Raw Data'!A20 -> 0.0138 | C13: =IF(OR('대시보드'!$A$35="☑",'대시보드'!$A$35=TRUE,'대시보드'!$A$35="TRUE",'대시보드'!$A$35=1),'Raw Data'!B20,NA()) -> -0.87
... A4801: 제품 | B4801: ='Raw Data'!A4808 -> 6 | C4801: =IF(OR('대시보드'!$A$35="☑",'대시보드'!$A$35=TRUE,'대시보드'!$A$35="TRUE",'대시보드'!$A$35=1),'Raw Data'!B4808,NA()) -> 2.06
A4802: 제품 | B4802: ='Raw Data'!D9 -> 0 | C4802: =IF(OR('대시보드'!$A$36="☑",'대시보드'!$A$36=TRUE,'대시보드'!$A$36="TRUE",'대시보드'!$A$36=1),'Raw Data'!E9,NA()) -> -8.22
A4803: 제품 | B4803: ='Raw Data'!D10 -> 0.0013 | C4803: =IF(OR('대시보드'!$A$36="☑",'대시보드'!$A$36=TRUE,'대시보드'!$A$36="TRUE",'대시보드'!$A$36=1),'Raw Data'!E10,NA()) -> -1.37
A4804: 제품 | B4804: ='Raw Data'!D11 -> 0.0025 | C4804: =IF(OR('대시보드'!$A$36="☑",'대시보드'!$A$36=TRUE,'대시보드'!$A$36="TRUE",'대시보드'!$A$36=1),'Raw Data'!E11,NA()) -> -0.91
A4805: 제품 | B4805: ='Raw Data'!D12 -> 0.0038 | C4805: =IF(OR('대시보드'!$A$36="☑",'대시보드'!$A$36=TRUE,'대시보드'!$A$36="TRUE",'대시보드'!$A$36=1),'Raw Data'!E12,NA()) -> -0.64
A4806: 제품 | B4806: ='Raw Data'!D13 -> 0.005 | C4806: =IF(OR('대시보드'!$A$36="☑",'대시보드'!$A$36=TRUE,'대시보드'!$A$36="TRUE",'대시보드'!$A$36=1),'Raw Data'!E13,NA()) -> -1.19
A4807: 제품 | B4807: ='Raw Data'!D14 -> 0.0063 | C4807: =IF(OR('대시보드'!$A$36="☑",'대시보드'!$A$36=TRUE,'대시보드'!$A$36="TRUE",'대시보드'!$A$36=1),'Raw Data'!E14,NA()) -> -1.37
A4808: 제품 | B4808: ='Raw Data'!D15 -> 0.0075 | C4808: =IF(OR('대시보드'!$A$36="☑",'대시보드'!$A$36=TRUE,'대시보드'!$A$36="TRUE",'대시보드'!$A$36=1),'Raw Data'!E15,NA()) -> -1.1
A4809: 제품 | B4809: ='Raw Data'!D16 -> 0.0088 | C4809: =IF(OR('대시보드'!$A$36="☑",'대시보드'!$A$36=TRUE,'대시보드'!$A$36="TRUE",'대시보드'!$A$36=1),'Raw Data'!E16,NA()) -> -0.91
A4810: 제품 | B4810: ='Raw Data'!D17 -> 0.01 | C4810: =IF(OR('대시보드'!$A$36="☑",'대시보드'!$A$36=TRUE,'대시보드'!$A$36="TRUE",'대시보드'!$A$36=1),'Raw Data'!E17,NA()) -> -1.37
A4811: 제품 | B4811: ='Raw Data'!D18 -> 0.0113 | C4811: =IF(OR('대시보드'!$A$36="☑",'대시보드'!$A$36=TRUE,'대시보드'!$A$36="TRUE",'대시보드'!$A$36=1),'Raw Data'!E18,NA()) -> -1.28
A4812: 제품 | B4812: ='Raw Data'!D19 -> 0.0125 | C4812: =IF(OR('대시보드'!$A$36="☑",'대시보드'!$A$36=TRUE,'대시보드'!$A$36="TRUE",'대시보드'!$A$36=1),'Raw Data'!E19,NA()) -> -0.91
A4813: 제품 | B4813: ='Raw Data'!D20 -> 0.0138 | C4813: =IF(OR('대시보드'!$A$36="☑",'대시보드'!$A$36=TRUE,'대시보드'!$A$36="TRUE",'대시보드'!$A$36=1),'Raw Data'!E20,NA()) -> -1.37
... A9601: 제품 | B9601: ='Raw Data'!D4808 -> 6 | C9601: =IF(OR('대시보드'!$A$36="☑",'대시보드'!$A$36=TRUE,'대시보드'!$A$36="TRUE",'대시보드'!$A$36=1),'Raw Data'!E4808,NA()) -> 11.32
A9602: 제품 | B9602: ='Raw Data'!G9 -> 0 | C9602: =IF(OR('대시보드'!$A$37="☑",'대시보드'!$A$37=TRUE,'대시보드'!$A$37="TRUE",'대시보드'!$A$37=1),'Raw Data'!H9,NA()) -> -9.88
A9603: 제품 | B9603: ='Raw Data'!G10 -> 0.0013 | C9603: =IF(OR('대시보드'!$A$37="☑",'대시보드'!$A$37=TRUE,'대시보드'!$A$37="TRUE",'대시보드'!$A$37=1),'Raw Data'!H10,NA()) -> -1.32
A9604: 제품 | B9604: ='Raw Data'!G11 -> 0.0025 | C9604: =IF(OR('대시보드'!$A$37="☑",'대시보드'!$A$37=TRUE,'대시보드'!$A$37="TRUE",'대시보드'!$A$37=1),'Raw Data'!H11,NA()) -> -1.87
A9605: 제품 | B9605: ='Raw Data'!G12 -> 0.0038 | C9605: =IF(OR('대시보드'!$A$37="☑",'대시보드'!$A$37=TRUE,'대시보드'!$A$37="TRUE",'대시보드'!$A$37=1),'Raw Data'!H12,NA()) -> -2.2
A9606: 제품 | B9606: ='Raw Data'!G13 -> 0.005 | C9606: =IF(OR('대시보드'!$A$37="☑",'대시보드'!$A$37=TRUE,'대시보드'!$A$37="TRUE",'대시보드'!$A$37=1),'Raw Data'!H13,NA()) -> -1.54
A9607: 제품 | B9607: ='Raw Data'!G14 -> 0.0063 | C9607: =IF(OR('대시보드'!$A$37="☑",'대시보드'!$A$37=TRUE,'대시보드'!$A$37="TRUE",'대시보드'!$A$37=1),'Raw Data'!H14,NA()) -> -1.76
A9608: 제품 | B9608: ='Raw Data'!G15 -> 0.0075 | C9608: =IF(OR('대시보드'!$A$37="☑",'대시보드'!$A$37=TRUE,'대시보드'!$A$37="TRUE",'대시보드'!$A$37=1),'Raw Data'!H15,NA()) -> -1.98
A9609: 제품 | B9609: ='Raw Data'!G16 -> 0.0088 | C9609: =IF(OR('대시보드'!$A$37="☑",'대시보드'!$A$37=TRUE,'대시보드'!$A$37="TRUE",'대시보드'!$A$37=1),'Raw Data'!H16,NA()) -> -1.87
A9610: 제품 | B9610: ='Raw Data'!G17 -> 0.01 | C9610: =IF(OR('대시보드'!$A$37="☑",'대시보드'!$A$37=TRUE,'대시보드'!$A$37="TRUE",'대시보드'!$A$37=1),'Raw Data'!H17,NA()) -> -1.98
A9611: 제품 | B9611: ='Raw Data'!G18 -> 0.0113 | C9611: =IF(OR('대시보드'!$A$37="☑",'대시보드'!$A$37=TRUE,'대시보드'!$A$37="TRUE",'대시보드'!$A$37=1),'Raw Data'!H18,NA()) -> -2.09
A9612: 제품 | B9612: ='Raw Data'!G19 -> 0.0125 | C9612: =IF(OR('대시보드'!$A$37="☑",'대시보드'!$A$37=TRUE,'대시보드'!$A$37="TRUE",'대시보드'!$A$37=1),'Raw Data'!H19,NA()) -> -2.09
A9613: 제품 | B9613: ='Raw Data'!G20 -> 0.0138 | C9613: =IF(OR('대시보드'!$A$37="☑",'대시보드'!$A$37=TRUE,'대시보드'!$A$37="TRUE",'대시보드'!$A$37=1),'Raw Data'!H20,NA()) -> -1.87
... A14401: 제품 | B14401: ='Raw Data'!G4808 -> 6 | C14401: =IF(OR('대시보드'!$A$37="☑",'대시보드'!$A$37=TRUE,'대시보드'!$A$37="TRUE",'대시보드'!$A$37=1),'Raw Data'!H4808,NA()) -> 12.52
...
