Workbook

Sheet 대시보드
A1: KEITHLEY 2400 · INTERACTIVE TEST DASHBOARD
A3: 샘플 선택 | 체크된 샘플만 아래 그래프에 표시됩니다.
A4: 선택 | B4: No | C4: 샘플명 | D4: 테스트 방법 | E4: 인가 설정 | F4: Compliance | G4: 측정 수 | H4: 평가 시간 (s) | I4: 상태
A5: TRUE | B5: 1 | C5: ='Raw Data'!B1 -> a | D5: 시간 · 4-Wire · 전압 인가 | E5: 9.0000 V | F5: 0.01000 A | G5: 47 | H5: 12.931 | I5: OK
A6: TRUE | B6: 2 | C6: ='Raw Data'!G1 -> b | D6: 시간 · 4-Wire · 전압 인가 | E6: 9.0000 V | F6: 0.01000 A | G6: 47 | H6: 12.886 | I6: OK
A9: 표시 항목 선택
A10: TRUE | B10: Voltage (V) ━━━ 실선 | E10: TRUE | F10: Current (A) ━ ━ 굵은 점선 | J10: TRUE | K10: Resistance (Ω) ····· 얇은 점선
A12: 전압 / 전류 / 저항 그래프
Q15: 5.0645038e+11
R20: Resistance (Ω)
Q25: 0
Q35: -5.0645038e+11
A39: ※ 왼쪽 Y축은 Voltage(V), 오른쪽 Y축은 Current(A)입니다. Resistance(Ω)는 원점을 유지한 선형 변환으로 같은 그래프에 표시하며, 오른쪽 녹색 보조 눈금은 실제 저항 단위입니다.
A40: 체크박스 변경 후 그래프가 즉시 갱신됩니다. 새 샘플을 추가할 때는 Raw Data 시트의 기존 5열 블록 구조와 1행 샘플명 위치를 유지해 주세요.

Sheet Raw Data
A1: 샘플명 | B1: a | F1: 샘플명 | G1: b
A2: 테스트 방법 | B2: 시간 · 4-Wire · 전압 인가 | F2: 테스트 방법 | G2: 시간 · 4-Wire · 전압 인가
A3: 평가 시각 | B3: 2026-08-26 14:29:20 | F3: 평가 시각 | G3: 2026-08-26 14:29:49
A4: 인가 설정 | B4: 9.0000 V | F4: 인가 설정 | G4: 9.0000 V
A5: Compliance | B5: 0.01000 A | F5: Compliance | G5: 0.01000 A
A6: 측정 수 / 평가 시간 | B6: 47 / 12.9310 s | F6: 측정 수 / 평가 시간 | G6: 47 / 12.8860 s
A7: 상태 | B7: OK | F7: 상태 | G7: OK
A8: 시간 (s) | B8: 전압 (V) | C8: 전류 (A) | D8: 저항 (Ω) | F8: 시간 (s) | G8: 전압 (V) | H8: 전류 (A) | I8: 저항 (Ω)
A9: 2.898 | B9: 9.000089 | C9: 5.114895e-11 | D9: 1.7595843e+11 | F9: 2.9 | G9: 9.000139 | H9: 1.037923e-09 | I9: 8.6712974e+09
A10: 3.425 | B10: 8.999978 | C10: 1.437514e-10 | D10: 6.2607933e+10 | F10: 3.394 | G10: 9.000002 | H10: 1.308656e-09 | I10: 6.8772863e+09
A11: 3.664 | B11: 9.000041 | C11: -4.00289e-10 | D11: -2.2483858e+10 | F11: 3.666 | G11: 8.999823 | H11: 1.412187e-10 | I11: 6.3729683e+10
A12: 3.84 | B12: 8.999915 | C12: -4.812744e-10 | D12: -1.8700174e+10 | F12: 3.825 | G12: 9.000125 | H12: 9.190021e-10 | I12: 9.7933672e+09
A13: 4.096 | B13: 9.000175 | C13: -5.37461e-10 | D13: -1.6745727e+10 | F13: 4.081 | G13: 9.000147 | H13: 1.586976e-09 | I13: 5.6712559e+09
A14: 4.289 | B14: 9.000156 | C14: -2.838698e-10 | D14: -3.1705225e+10 | F14: 4.307 | G14: 9.000064 | H14: 2.085248e-10 | I14: 4.3160641e+10
A15: 4.51 | B15: 8.999999 | C15: 1.385566e-09 | D15: 6.4955397e+09 | F15: 4.497 | G15: 9.000013 | H15: 1.36887e-09 | I15: 6.5747755e+09
A16: 4.719 | B16: 9.000067 | C16: 1.509041e-09 | D16: 5.9640971e+09 | F16: 4.719 | G16: 8.999966 | H16: 4.98484e-10 | I16: 1.8054674e+10
A17: 4.926 | B17: 8.999983 | C17: 4.544593e-10 | D17: 1.9803716e+10 | F17: 4.928 | G17: 9.000031 | H17: 1.43668e-09 | I17: 6.2644646e+09
A18: 5.151 | B18: 8.999994 | C18: 1.398215e-09 | D18: 6.436774e+09 | F18: 5.135 | G18: 9.000134 | H18: 4.301679e-10 | I18: 2.0922375e+10
A19: 5.359 | B19: 8.999892 | C19: -6.634949e-10 | D19: -1.3564373e+10 | F19: 5.36 | G19: 8.99991 | H19: 1.323323e-09 | I19: 6.8009927e+09
A20: 5.567 | B20: 8.99998 | C20: -3.046222e-10 | D20: -2.9544728e+10 | F20: 5.552 | G20: 9.00005 | H20: 1.022738e-09 | I20: 8.7999566e+09
... A55: 12.931 | B55: 9.00003 | C55: -7.272741e-10 | D55: -1.2375018e+10 | F55: 12.886 | G55: 9.000168 | H55: 1.462991e-09 | I55: 6.1518957e+09

Sheet _ChartData
A1: Sample | B1: Metric | C1: Time | D1: Display | E1: Raw
A2: a | B2: Voltage | C2: =IF(AND(대시보드!$A$5,대시보드!$A$10),'Raw Data'!A9,NA()) -> 2.898 | D2: =IF(AND(대시보드!$A$5,대시보드!$A$10),'Raw Data'!B9,NA()) -> 9.000089 | E2: ='Raw Data'!B9 -> 9.000089
A3: a | B3: Voltage | C3: =IF(AND(대시보드!$A$5,대시보드!$A$10),'Raw Data'!A10,NA()) -> 3.425 | D3: =IF(AND(대시보드!$A$5,대시보드!$A$10),'Raw Data'!B10,NA()) -> 8.999978 | E3: ='Raw Data'!B10 -> 8.999978
A4: a | B4: Voltage | C4: =IF(AND(대시보드!$A$5,대시보드!$A$10),'Raw Data'!A11,NA()) -> 3.664 | D4: =IF(AND(대시보드!$A$5,대시보드!$A$10),'Raw Data'!B11,NA()) -> 9.000041 | E4: ='Raw Data'!B11 -> 9.000041
A5: a | B5: Voltage | C5: =IF(AND(대시보드!$A$5,대시보드!$A$10),'Raw Data'!A12,NA()) -> 3.84 | D5: =IF(AND(대시보드!$A$5,대시보드!$A$10),'Raw Data'!B12,NA()) -> 8.999915 | E5: ='Raw Data'!B12 -> 8.999915
A6: a | B6: Voltage | C6: =IF(AND(대시보드!$A$5,대시보드!$A$10),'Raw Data'!A13,NA()) -> 4.096 | D6: =IF(AND(대시보드!$A$5,대시보드!$A$10),'Raw Data'!B13,NA()) -> 9.000175 | E6: ='Raw Data'!B13 -> 9.000175
A7: a | B7: Voltage | C7: =IF(AND(대시보드!$A$5,대시보드!$A$10),'Raw Data'!A14,NA()) -> 4.289 | D7: =IF(AND(대시보드!$A$5,대시보드!$A$10),'Raw Data'!B14,NA()) -> 9.000156 | E7: ='Raw Data'!B14 -> 9.000156
A8: a | B8: Voltage | C8: =IF(AND(대시보드!$A$5,대시보드!$A$10),'Raw Data'!A15,NA()) -> 4.51 | D8: =IF(AND(대시보드!$A$5,대시보드!$A$10),'Raw Data'!B15,NA()) -> 8.999999 | E8: ='Raw Data'!B15 -> 8.999999
A9: a | B9: Voltage | C9: =IF(AND(대시보드!$A$5,대시보드!$A$10),'Raw Data'!A16,NA()) -> 4.719 | D9: =IF(AND(대시보드!$A$5,대시보드!$A$10),'Raw Data'!B16,NA()) -> 9.000067 | E9: ='Raw Data'!B16 -> 9.000067
A10: a | B10: Voltage | C10: =IF(AND(대시보드!$A$5,대시보드!$A$10),'Raw Data'!A17,NA()) -> 4.926 | D10: =IF(AND(대시보드!$A$5,대시보드!$A$10),'Raw Data'!B17,NA()) -> 8.999983 | E10: ='Raw Data'!B17 -> 8.999983
A11: a | B11: Voltage | C11: =IF(AND(대시보드!$A$5,대시보드!$A$10),'Raw Data'!A18,NA()) -> 5.151 | D11: =IF(AND(대시보드!$A$5,대시보드!$A$10),'Raw Data'!B18,NA()) -> 8.999994 | E11: ='Raw Data'!B18 -> 8.999994
A12: a | B12: Voltage | C12: =IF(AND(대시보드!$A$5,대시보드!$A$10),'Raw Data'!A19,NA()) -> 5.359 | D12: =IF(AND(대시보드!$A$5,대시보드!$A$10),'Raw Data'!B19,NA()) -> 8.999892 | E12: ='Raw Data'!B19 -> 8.999892
A13: a | B13: Voltage | C13: =IF(AND(대시보드!$A$5,대시보드!$A$10),'Raw Data'!A20,NA()) -> 5.567 | D13: =IF(AND(대시보드!$A$5,대시보드!$A$10),'Raw Data'!B20,NA()) -> 8.99998 | E13: ='Raw Data'!B20 -> 8.99998
... A48: a | B48: Voltage | C48: =IF(AND(대시보드!$A$5,대시보드!$A$10),'Raw Data'!A55,NA()) -> 12.931 | D48: =IF(AND(대시보드!$A$5,대시보드!$A$10),'Raw Data'!B55,NA()) -> 9.00003 | E48: ='Raw Data'!B55 -> 9.00003
A49: a | B49: Current | C49: =IF(AND(대시보드!$A$5,대시보드!$E$10),'Raw Data'!A9,NA()) -> 2.898 | D49: =IF(AND(대시보드!$A$5,대시보드!$E$10),'Raw Data'!C9,NA()) -> 5.114895e-11 | E49: ='Raw Data'!C9 -> 5.114895e-11
A50: a | B50: Current | C50: =IF(AND(대시보드!$A$5,대시보드!$E$10),'Raw Data'!A10,NA()) -> 3.425 | D50: =IF(AND(대시보드!$A$5,대시보드!$E$10),'Raw Data'!C10,NA()) -> 1.437514e-10 | E50: ='Raw Data'!C10 -> 1.437514e-10
A51: a | B51: Current | C51: =IF(AND(대시보드!$A$5,대시보드!$E$10),'Raw Data'!A11,NA()) -> 3.664 | D51: =IF(AND(대시보드!$A$5,대시보드!$E$10),'Raw Data'!C11,NA()) -> -4.00289e-10 | E51: ='Raw Data'!C11 -> -4.00289e-10
A52: a | B52: Current | C52: =IF(AND(대시보드!$A$5,대시보드!$E$10),'Raw Data'!A12,NA()) -> 3.84 | D52: =IF(AND(대시보드!$A$5,대시보드!$E$10),'Raw Data'!C12,NA()) -> -4.812744e-10 | E52: ='Raw Data'!C12 -> -4.812744e-10
A53: a | B53: Current | C53: =IF(AND(대시보드!$A$5,대시보드!$E$10),'Raw Data'!A13,NA()) -> 4.096 | D53: =IF(AND(대시보드!$A$5,대시보드!$E$10),'Raw Data'!C13,NA()) -> -5.37461e-10 | E53: ='Raw Data'!C13 -> -5.37461e-10
A54: a | B54: Current | C54: =IF(AND(대시보드!$A$5,대시보드!$E$10),'Raw Data'!A14,NA()) -> 4.289 | D54: =IF(AND(대시보드!$A$5,대시보드!$E$10),'Raw Data'!C14,NA()) -> -2.838698e-10 | E54: ='Raw Data'!C14 -> -2.838698e-10
A55: a | B55: Current | C55: =IF(AND(대시보드!$A$5,대시보드!$E$10),'Raw Data'!A15,NA()) -> 4.51 | D55: =IF(AND(대시보드!$A$5,대시보드!$E$10),'Raw Data'!C15,NA()) -> 1.385566e-09 | E55: ='Raw Data'!C15 -> 1.385566e-09
A56: a | B56: Current | C56: =IF(AND(대시보드!$A$5,대시보드!$E$10),'Raw Data'!A16,NA()) -> 4.719 | D56: =IF(AND(대시보드!$A$5,대시보드!$E$10),'Raw Data'!C16,NA()) -> 1.509041e-09 | E56: ='Raw Data'!C16 -> 1.509041e-09
A57: a | B57: Current | C57: =IF(AND(대시보드!$A$5,대시보드!$E$10),'Raw Data'!A17,NA()) -> 4.926 | D57: =IF(AND(대시보드!$A$5,대시보드!$E$10),'Raw Data'!C17,NA()) -> 4.544593e-10 | E57: ='Raw Data'!C17 -> 4.544593e-10
A58: a | B58: Current | C58: =IF(AND(대시보드!$A$5,대시보드!$E$10),'Raw Data'!A18,NA()) -> 5.151 | D58: =IF(AND(대시보드!$A$5,대시보드!$E$10),'Raw Data'!C18,NA()) -> 1.398215e-09 | E58: ='Raw Data'!C18 -> 1.398215e-09
A59: a | B59: Current | C59: =IF(AND(대시보드!$A$5,대시보드!$E$10),'Raw Data'!A19,NA()) -> 5.359 | D59: =IF(AND(대시보드!$A$5,대시보드!$E$10),'Raw Data'!C19,NA()) -> -6.634949e-10 | E59: ='Raw Data'!C19 -> -6.634949e-10
A60: a | B60: Current | C60: =IF(AND(대시보드!$A$5,대시보드!$E$10),'Raw Data'!A20,NA()) -> 5.567 | D60: =IF(AND(대시보드!$A$5,대시보드!$E$10),'Raw Data'!C20,NA()) -> -3.046222e-10 | E60: ='Raw Data'!C20 -> -3.046222e-10
... A95: a | B95: Current | C95: =IF(AND(대시보드!$A$5,대시보드!$E$10),'Raw Data'!A55,NA()) -> 12.931 | D95: =IF(AND(대시보드!$A$5,대시보드!$E$10),'Raw Data'!C55,NA()) -> -7.272741e-10 | E95: ='Raw Data'!C55 -> -7.272741e-10
A96: a | B96: Resistance | C96: =IF(AND(대시보드!$A$5,대시보드!$J$10),'Raw Data'!A9,NA()) -> 2.898 | D96: =IF(AND(대시보드!$A$5,대시보드!$J$10),('Raw Data'!D9)*(0.00000000171393408/506450380903.8),NA()) -> 5.9548016e-10 | E96: ='Raw Data'!D9 -> 1.7595843e+11
A97: a | B97: Resistance | C97: =IF(AND(대시보드!$A$5,대시보드!$J$10),'Raw Data'!A10,NA()) -> 3.425 | D97: =IF(AND(대시보드!$A$5,대시보드!$J$10),('Raw Data'!D10)*(0.00000000171393408/506450380903.8),NA()) -> 2.1187835e-10 | E97: ='Raw Data'!D10 -> 6.2607933e+10
A98: a | B98: Resistance | C98: =IF(AND(대시보드!$A$5,대시보드!$J$10),'Raw Data'!A11,NA()) -> 3.664 | D98: =IF(AND(대시보드!$A$5,대시보드!$J$10),('Raw Data'!D11)*(0.00000000171393408/506450380903.8),NA()) -> -7.6090081e-11 | E98: ='Raw Data'!D11 -> -2.2483858e+10
A99: a | B99: Resistance | C99: =IF(AND(대시보드!$A$5,대시보드!$J$10),'Raw Data'!A12,NA()) -> 3.84 | D99: =IF(AND(대시보드!$A$5,대시보드!$J$10),('Raw Data'!D12)*(0.00000000171393408/506450380903.8),NA()) -> -6.3285302e-11 | E99: ='Raw Data'!D12 -> -1.8700174e+10
A100: a | B100: Resistance | C100: =IF(AND(대시보드!$A$5,대시보드!$J$10),'Raw Data'!A13,NA()) -> 4.096 | D100: =IF(AND(대시보드!$A$5,대시보드!$J$10),('Raw Data'!D13)*(0.00000000171393408/506450380903.8),NA()) -> -5.6671044e-11 | E100: ='Raw Data'!D13 -> -1.6745727e+10
A101: a | B101: Resistance | C101: =IF(AND(대시보드!$A$5,대시보드!$J$10),'Raw Data'!A14,NA()) -> 4.289 | D101: =IF(AND(대시보드!$A$5,대시보드!$J$10),('Raw Data'!D14)*(0.00000000171393408/506450380903.8),NA()) -> -1.0729712e-10 | E101: ='Raw Data'!D14 -> -3.1705225e+10
A102: a | B102: Resistance | C102: =IF(AND(대시보드!$A$5,대시보드!$J$10),'Raw Data'!A15,NA()) -> 4.51 | D102: =IF(AND(대시보드!$A$5,대시보드!$J$10),('Raw Data'!D15)*(0.00000000171393408/506450380903.8),NA()) -> 2.1982266e-11 | E102: ='Raw Data'!D15 -> 6.4955397e+09
A103: a | B103: Resistance | C103: =IF(AND(대시보드!$A$5,대시보드!$J$10),'Raw Data'!A16,NA()) -> 4.719 | D103: =IF(AND(대시보드!$A$5,대시보드!$J$10),('Raw Data'!D16)*(0.00000000171393408/506450380903.8),NA()) -> 2.0183753e-11 | E103: ='Raw Data'!D16 -> 5.9640971e+09
A104: a | B104: Resistance | C104: =IF(AND(대시보드!$A$5,대시보드!$J$10),'Raw Data'!A17,NA()) -> 4.926 | D104: =IF(AND(대시보드!$A$5,대시보드!$J$10),('Raw Data'!D17)*(0.00000000171393408/506450380903.8),NA()) -> 6.701992e-11 | E104: ='Raw Data'!D17 -> 1.9803716e+10
A105: a | B105: Resistance | C105: =IF(AND(대시보드!$A$5,대시보드!$J$10),'Raw Data'!A18,NA()) -> 5.151 | D105: =IF(AND(대시보드!$A$5,대시보드!$J$10),('Raw Data'!D18)*(0.00000000171393408/506450380903.8),NA()) -> 2.178339e-11 | E105: ='Raw Data'!D18 -> 6.436774e+09
A106: a | B106: Resistance | C106: =IF(AND(대시보드!$A$5,대시보드!$J$10),'Raw Data'!A19,NA()) -> 5.359 | D106: =IF(AND(대시보드!$A$5,대시보드!$J$10),('Raw Data'!D19)*(0.00000000171393408/506450380903.8),NA()) -> -4.5904675e-11 | E106: ='Raw Data'!D19 -> -1.3564373e+10
A107: a | B107: Resistance | C107: =IF(AND(대시보드!$A$5,대시보드!$J$10),'Raw Data'!A20,NA()) -> 5.567 | D107: =IF(AND(대시보드!$A$5,대시보드!$J$10),('Raw Data'!D20)*(0.00000000171393408/506450380903.8),NA()) -> -9.9985542e-11 | E107: ='Raw Data'!D20 -> -2.9544728e+10
... A142: a | B142: Resistance | C142: =IF(AND(대시보드!$A$5,대시보드!$J$10),'Raw Data'!A55,NA()) -> 12.931 | D142: =IF(AND(대시보드!$A$5,대시보드!$J$10),('Raw Data'!D55)*(0.00000000171393408/506450380903.8),NA()) -> -4.187965e-11 | E142: ='Raw Data'!D55 -> -1.2375018e+10
...
